<?xml version="1.0"?>
<robot xmlns:xacro="http://www.ros.org/wiki/xacro" name="simp">

<xacro:property name="length" value="1.0" />
<xacro:property name="radius" value="0.1" />
<xacro:property name="mass" value="10" />

<xacro:macro name="default_shape">
	<geometry>
	     <cylinder length="${length}" radius="${radius}"/>
	</geometry>
</xacro:macro>

<xacro:macro name="default_inertia">
	  <inertial>
		<mass value="10" />
                <inertia ixx="1.0" ixy="0.0" ixz="0.0"
                     iyy="1.0" iyz="0.0"
                     izz="1.0" />
	  </inertial>
</xacro:macro>

<link name="base_link"/>


 <link name = "link_0">
         <visual>
		<origin rpy="0 1.57 0" xyz="0.5 0 0" />
		<xacro:default_shape />
	  </visual>
	  <collision>
		<xacro:default_shape />
	  </collision>
	  <xacro:default_inertia/>
</link>

<joint name="b0" type="revolute">
       <parent link="base_link"/>
       <child link="link_0"/>
       <axis xyz="0 0 1"/>
       <limit effort="30.0" lower="0.0" upper="3.14" velocity="0.5"/>
       <dynamics damping="0.01" friction="0.01"/>
       <origin rpy="0 0 0" xyz="0 0 0"/>
</joint>


<transmission name="base_to_0_trans">
    <type>transmission_interface/SimpleTransmission</type>
    <actuator name="base_to_0_motor">
      <mechanicalReduction>1</mechanicalReduction>
    </actuator>
    <joint name="b0">
      <hardwareInterface>hardware_interface/PositionJointInterface</hardwareInterface>
    </joint>
  </transmission>

  
<gazebo>
    <plugin name="gazebo_ros_control" filename="libgazebo_ros_control.so">
      <robotNamespace>/</robotNamespace>
    </plugin>
</gazebo>


</robot>
